<mujoco model="T1">
  <compiler angle="radian" assetdir="assets" autolimits="true"/>

  <option cone="pyramidal" impratio="1" solver="Newton" iterations="1" ls_iterations="4" density="1.2" viscosity="0.00002">
    <flag eulerdamp="disable"/>
  </option>

  <default>
    <site size="0.01" group="5"/>
    <geom solref="-1000 -80" contype="0" conaffinity="0" group="1"/>
    <joint damping="0.01" armature="0.01" frictionloss="0.1"/>
    <position forcelimited="true" kp="25" kv="0.6"/>

    <default class="t1">
      <geom rgba="0.25 0.25 0.25 1"/>
      <default class="visual">
        <geom type="mesh" contype="0" conaffinity="0" group="2"/>
      </default>
      <default class="collision">
        <geom group="3"/>
      </default>

      <default class="foot">
        <geom type="box" size="0.1115 0.05 0.015" solimp="0.015 1 0.015" pos="0.01 0 -0.015" priority="1" condim="6" friction="1.0 0.01 0.005" group="4"/>
        <site pos="0.01 0 -0.015"/>
      </default>

      <default class="reward_collision_sphere">
        <geom group="5" rgba="1 0 0 1"/>
      </default>
    </default>
  </default>

  <asset>
    <mesh name="Trunk" file="Trunk.STL"/>
    <mesh name="H1" file="H1.STL"/>
    <mesh name="H2" file="H2.STL"/>
    <mesh name="AL1" file="AL1.STL"/>
    <mesh name="AL2" file="AL2.STL"/>
    <mesh name="AL3" file="AL3.STL"/>
    <mesh name="left_hand_link" file="left_hand_link.STL"/>
    <mesh name="AR1" file="AL1.STL" scale="1 -1 1"/>
    <mesh name="AR2" file="AL2.STL" scale="1 -1 1"/>
    <mesh name="AR3" file="AL3.STL" scale="1 -1 1"/>
    <mesh name="right_hand_link" file="left_hand_link.STL" scale="1 -1 1"/>
    <mesh name="Waist" file="Waist.STL"/>
    <mesh name="Hip_Pitch_Left" file="Hip_Pitch_Left.STL"/>
    <mesh name="Hip_Roll_Left" file="Hip_Roll.STL"/>
    <mesh name="Hip_Yaw_Left" file="Hip_Yaw.STL"/>
    <mesh name="Shank_Left" file="Shank_Left.STL"/>
    <mesh name="Ankle_Cross_Left" file="Ankle_Cross_Left.STL"/>
    <mesh name="left_foot_link" file="foot_link.STL"/>
    <mesh name="Hip_Pitch_Right" file="Hip_Pitch_Left.STL" scale="1 -1 1"/>
    <mesh name="Hip_Roll_Right" file="Hip_Roll.STL"/>
    <mesh name="Hip_Yaw_Right" file="Hip_Yaw.STL"/>
    <mesh name="Shank_Right" file="Shank_Left.STL" scale="1 -1 1"/>
    <mesh name="Ankle_Cross_Right" file="Ankle_Cross_Left.STL" scale="1 -1 1"/>
    <mesh name="right_foot_link" file="foot_link.STL"/>
    <material name="gray" rgba="0.4 0.4 0.4 1"/>
    <material name="team" rgba="0.4 0.4 0.4 1"/>

    <texture type="skybox" builtin="gradient" rgb1="0.95 0.95 0.95" rgb2="0.95 0.95 0.95" width="100" height="100" />
    <texture name="texplane" type="2d" builtin="checker" rgb1="0.3 0.55 0.3" rgb2="0.3 0.55 0.3" mark="edge" markrgb="1.0 1.0 1.0" width="512" height="512"/>
    <material name="MatPlane" texture="texplane" texrepeat="2 2" texuniform="true" specular="0.9" shininess="0.5" reflectance="0.0" rgba="1 1 1 1"/>
  </asset>

  <worldbody>
    <geom name="floor" pos="0 0 0" material="MatPlane" size="100 100 0.125" type="plane" group="0"/>
    <light name="toplight1" directional="true" dir="1 0 -0.5" diffuse="0.2 0.2 0.2" specular="0.3 0.3 0.3" ambient="0.01 0.01 0.01" castshadow="true"/>
    <light name="toplight2" directional="true" dir="-1 0 -0.5" diffuse="0.2 0.2 0.2" specular="0.3 0.3 0.3" ambient="0.01 0.01 0.01" castshadow="true"/>
    <light name="toplight3" directional="true" dir="0 1 -0.5" diffuse="0.2 0.2 0.2" specular="0.3 0.3 0.3" ambient="0.01 0.01 0.01" castshadow="true"/>
    <light name="toplight4" directional="true" dir="0 -1 -1" diffuse="0.2 0.2 0.2" specular="0.3 0.3 0.3" ambient="0.01 0.01 0.01" castshadow="true"/>
    <light name="spotlight" mode="targetbodycom" target="trunk" pos="0 0 2" diffuse="0.4 0.4 0.4" specular="0.3 0.3 0.3" cutoff="10" castshadow="false"/>

    <body name="trunk" pos="0 0 0" childclass="t1">
      <camera name="track" mode="trackcom" pos="0 -2 0" xyaxes="1 0 0 0 0 1"/>
      
      <freejoint/>

      <site name="imu" pos="0 0 0"/>

      <inertial pos="0.0551365 -1.42058e-06 0.105062" quat="0.99996 1.40561e-05 -0.00899532 -1.39249e-05" mass="11.7" diaginertia="0.0915404 0.0767787 0.0556055"/>

      <geom class="visual" material="team" mesh="Trunk"/>
      <geom class="collision" size="0.075 0.1 0.15" pos="0.06 0 0.12" type="box"/>
      <geom class="reward_collision_sphere" pos="0.06 0 0.1" size="0.115"/>
      <geom class="reward_collision_sphere" pos="0.06 0.085 0" size="0.015"/>
      <geom class="reward_collision_sphere" pos="0.06 -0.085 0" size="0.015"/>
      <geom class="reward_collision_sphere" pos="0.06 0.107 0.18" size="0.015"/>
      <geom class="reward_collision_sphere" pos="0.06 -0.107 0.18" size="0.015"/>

      <camera name="ego_camera" pos="0.122 0 0.42" quat="-0.5 -0.5 0.5 0.5"/>

      <body name="H1" pos="0.0625 0 0.243">
        <inertial pos="-0.000508 -0.001403 0.057432" quat="0.763881 -0.0132172 0.00173419 0.645219" mass="0.44391" diaginertia="0.000241549 0.00022351 0.000149941"/>
        <joint name="AAHead_yaw" axis="0 0 1" range="-1.57 1.57"/>
        <geom class="visual" material="gray" mesh="H1"/>
        <body name="H2" pos="0 0 0.06185">
          <inertial pos="0.007802 0.001262 0.098631" quat="0.988453 0.106172 -0.0745686 -0.0782786" mass="0.631019" diaginertia="0.00203553 0.00192467 0.00172381"/>
          <joint name="Head_pitch" axis="0 1 0" range="-0.35 1.22"/>
          <geom class="visual" material="gray" mesh="H2"/>
          <geom class="collision" size="0.08" pos="0.01 0 0.11"/>
          <geom class="reward_collision_sphere" pos="0.02 0 0.1" size="0.09"/>
        </body>
      </body>
      <body name="AL1" pos="0.0575 0.1063 0.219" quat="1 0 0.000440565 0">
        <inertial pos="-0.000677 0.044974 0" quat="0.50423 0.495734 -0.50423 0.495734" mass="0.53" diaginertia="0.001367 0.00129329 0.000292711"/>
        <joint name="Left_Shoulder_Pitch" axis="0 1 0" range="-3.31 1.22"/>
        <geom class="visual" material="gray" mesh="AL1"/>
        <body name="AL2" pos="0 0.047 0">
          <inertial pos="0.003862 0.037976 0" quat="0.487991 0.511727 -0.487991 0.511727" mass="0.16" diaginertia="0.000401 0.00034538 0.00017662"/>
          <joint name="Left_Shoulder_Roll" axis="1 0 0" range="-1.74 1.57"/>
          <geom class="visual" material="gray" mesh="AL2"/>
          <body name="AL3" pos="0.00025 0.0605 0">
            <inertial pos="0 0.085353 -9.9e-05" quat="0.70641 0.707803 0 0" mass="1.02" diaginertia="0.012869 0.012798 0.000620953"/>
            <joint name="Left_Elbow_Pitch" axis="0 1 0" range="-2.27 2.27"/>
            <geom class="visual" material="gray" mesh="AL3"/>
            <geom class="collision" size="0.03 0.075" pos="0 0.05 0" quat="0.707105 0.707108 0 0" type="cylinder"/>
            <geom class="reward_collision_sphere" pos="0 0 0" size="0.036"/>
            <body name="left_hand_link" pos="0 0.1471 0">
              <inertial pos="-0.000108 0.109573 0.000591" quat="0.707866 0.706347 -5.22939e-05 -0.000214913" mass="0.327214" diaginertia="0.008159 0.00813104 0.000214962"/>
              <joint name="Left_Elbow_Yaw" axis="0 0 1" range="-2.44 0"/>
              <geom class="visual" material="gray" mesh="left_hand_link"/>
              <geom class="collision" size="0.03 0.0875" pos="0 0.13 0" quat="0.707105 0.707108 0 0" type="cylinder"/>
              <geom class="reward_collision_sphere" pos="0 0 0" size="0.05"/>
              <geom class="reward_collision_sphere" pos="0 0.11 0" size="0.035"/>
              <geom class="reward_collision_sphere" pos="0 0.215 0" size="0.035"/>
            </body>
          </body>
        </body>
      </body>
      <body name="AR1" pos="0.0575 -0.1063 0.219" quat="1 0 0.000440565 0">
        <inertial pos="-0.000677 -0.044974 0" quat="0.50423 0.495734 -0.50423 0.495734" mass="0.53" diaginertia="0.001367 0.00129329 0.000292711"/>
        <joint name="Right_Shoulder_Pitch" axis="0 1 0" range="-3.31 1.22"/>
        <geom class="visual" material="gray" mesh="AR1"/>
        <body name="AR2" pos="0 -0.047 0">
          <inertial pos="0.003862 -0.037976 0" quat="0.511727 0.487991 -0.511727 0.487991" mass="0.16" diaginertia="0.000401 0.00034538 0.00017662"/>
          <joint name="Right_Shoulder_Roll" axis="1 0 0" range="-1.57 1.74"/>
          <geom class="visual" material="gray" mesh="AR2"/>
          <body name="AR3" pos="0.00025 -0.0605 0">
            <inertial pos="0 -0.085353 -9.9e-05" quat="0.707803 0.70641 0 0" mass="1.02" diaginertia="0.012869 0.012798 0.000620953"/>
            <joint name="Right_Elbow_Pitch" axis="0 1 0" range="-2.27 2.27"/>
            <geom class="visual" material="gray" mesh="AR3"/>
            <geom class="collision" size="0.03 0.075" pos="0 -0.05 0" quat="0.707105 0.707108 0 0" type="cylinder"/>
            <geom class="reward_collision_sphere" pos="0 0 0" size="0.036"/>
            <body name="right_hand_link" pos="0 -0.1471 0">
              <inertial pos="-0.000108 -0.109573 0.000591" quat="0.706347 0.707866 0.000214913 5.22939e-05" mass="0.327214" diaginertia="0.008159 0.00813104 0.000214962"/>
              <joint name="Right_Elbow_Yaw" axis="0 0 1" range="0 2.44"/>
              <geom class="visual" material="gray" mesh="right_hand_link"/>
              <geom class="collision" size="0.03 0.0875" pos="0 -0.13 0" quat="0.707105 0.707108 0 0" type="cylinder"/>
              <geom class="reward_collision_sphere" pos="0 0 0" size="0.05"/>
              <geom class="reward_collision_sphere" pos="0 -0.11 0" size="0.035"/>
              <geom class="reward_collision_sphere" pos="0 -0.215 0" size="0.035"/>
            </body>
          </body>
        </body>
      </body>
      <body name="Waist" pos="0.0625 0 -0.1155">
        <inertial pos="0.002284 3e-06 0.007301" quat="0.983649 0.000360386 -0.180076 0.00269791" mass="2.581" diaginertia="0.00536742 0.005299 0.00474258"/>
        <joint name="Waist" axis="0 0 1" range="-1.57 1.57"/>
        <geom class="visual" material="gray" mesh="Waist"/>
        <body name="Hip_Pitch_Left" pos="0 0.106 0">
          <inertial pos="0.000534 -0.007296 -0.018083" quat="0.975141 0.2211 0.0145808 0.0017406" mass="1.021" diaginertia="0.00180547 0.00145926 0.00125327"/>
          <joint name="Left_Hip_Pitch" axis="0 1 0" range="-1.8 1.57"/>
          <geom class="visual" material="gray" mesh="Hip_Pitch_Left"/>
          <body name="Hip_Roll_Left" pos="0 0 -0.02">
            <inertial pos="0.001101 2.4e-05 -0.05375" quat="0.707081 -0.00599604 -0.00599604 0.707081" mass="0.385" diaginertia="0.001743 0.00151729 0.000514712"/>
            <joint name="Left_Hip_Roll" axis="1 0 0" range="-0.2 1.57"/>
            <geom class="visual" material="gray" mesh="Hip_Roll_Left"/>
            <geom class="reward_collision_sphere" pos="0 0 0" size="0.055"/>
            <body name="Hip_Yaw_Left" pos="0 0 -0.081854">
              <inertial pos="-0.007233 0.000206 -0.089184" quat="0.696808 -0.033953 -0.0315708 0.715758" mass="2.166" diaginertia="0.0257334 0.0253024 0.00259215"/>
              <joint name="Left_Hip_Yaw" axis="0 0 1" range="-1 1"/>
              <geom class="visual" material="gray" mesh="Hip_Yaw_Left"/>
              <geom class="collision" size="0.05 0.08" type="cylinder"/>
              <body name="Shank_Left" pos="-0.014 0 -0.134">
                <inertial pos="-0.006012 0.000259 -0.124318" quat="0.997573 0.00144024 -0.023949 0.0653706" mass="1.73" diaginertia="0.0346951 0.0345375 0.00185844"/>
                <joint name="Left_Knee_Pitch" axis="0 1 0" range="0 2.34"/>
                <geom class="visual" material="gray" mesh="Shank_Left"/>
                <geom class="collision" size="0.05 0.075" pos="0 0 -0.12" type="cylinder"/>
                <geom class="reward_collision_sphere" pos="0 0 0" size="0.065"/>
                <body name="Ankle_Cross_Left" pos="0 0 -0.28">
                  <inertial pos="-0.003722 0 -0.007981" quat="0.443136 0.551027 0.551027 0.443136" mass="0.073" diaginertia="2.9e-05 2.56589e-05 1.13411e-05"/>
                  <joint name="Left_Ankle_Pitch" axis="0 1 0" range="-0.87 0.35"/>
                  <geom class="visual" material="gray" mesh="Ankle_Cross_Left"/>
                  <body name="left_foot_link" pos="0 0.00025 -0.012">
                    <inertial pos="-0.000249 0 -0.00914" quat="0 0.679927 0 0.733279" mass="0.685" diaginertia="0.00268212 0.002385 0.000726885"/>
                    <joint name="Left_Ankle_Roll" axis="1 0 0" range="-0.44 0.44"/>
                    <geom class="visual" material="gray" mesh="left_foot_link"/>
                    <geom name="left_foot" class="foot"/>
                    <site name="left_foot" class="foot"/>
                    <geom class="reward_collision_sphere" pos="0.01 0 -0.015" size="0.052"/>
                    <geom class="reward_collision_sphere" pos="0.095 -0.023 -0.015" size="0.03"/>
                    <geom class="reward_collision_sphere" pos="-0.07 -0.023 -0.015" size="0.03"/>
                  </body>
                </body>
              </body>
            </body>
          </body>
        </body>
        <body name="Hip_Pitch_Right" pos="0 -0.106 0">
          <inertial pos="0.000534 0.007514 -0.018082" quat="0.973446 -0.228403 0.0147148 -0.00419349" mass="1.021" diaginertia="0.00180552 0.0014632 0.00124928"/>
          <joint name="Right_Hip_Pitch" axis="0 1 0" range="-1.8 1.57"/>
          <geom class="visual" material="gray" mesh="Hip_Pitch_Right"/>
          <body name="Hip_Roll_Right" pos="0 0 -0.02">
            <inertial pos="0.001099 2.4e-05 -0.053748" quat="0.707081 -0.00599604 -0.00599604 0.707081" mass="0.385" diaginertia="0.001743 0.00151729 0.000514712"/>
            <joint name="Right_Hip_Roll" axis="1 0 0" range="-1.57 0.2"/>
            <geom class="visual" material="gray" mesh="Hip_Roll_Right"/>
            <geom class="reward_collision_sphere" pos="0 0 0" size="0.055"/>
            <body name="Hip_Yaw_Right" pos="0 0 -0.081854">
              <inertial pos="-0.007191 -0.000149 -0.08922" quat="0.714468 -0.0315638 -0.0336391 0.698146" mass="2.17" diaginertia="0.0257623 0.0253298 0.00259389"/>
              <joint name="Right_Hip_Yaw" axis="0 0 1" range="-1 1"/>
              <geom class="visual" material="gray" mesh="Hip_Yaw_Right"/>
              <geom class="collision" size="0.05 0.08" type="cylinder"/>
              <body name="Shank_Right" pos="-0.014 0 -0.134">
                <inertial pos="-0.005741 -0.000541 -0.122602" quat="0.99926 -0.000580963 -0.023461 -0.0304754" mass="1.79" diaginertia="0.0351717 0.0349574 0.00196589"/>
                <joint name="Right_Knee_Pitch" axis="0 1 0" range="0 2.34"/>
                <geom class="visual" material="gray" mesh="Shank_Right"/>
                <geom class="collision" size="0.05 0.075" pos="0 0 -0.12" type="cylinder"/>
                <geom class="reward_collision_sphere" pos="0 0 0" size="0.065"/>
                <body name="Ankle_Cross_Right" pos="0 0 -0.28">
                  <inertial pos="-0.003722 0 -0.007981" quat="0.443136 0.551027 0.551027 0.443136" mass="0.073" diaginertia="2.9e-05 2.56589e-05 1.13411e-05"/>
                  <joint name="Right_Ankle_Pitch" axis="0 1 0" range="-0.87 0.35"/>
                  <geom class="visual" material="gray" mesh="Ankle_Cross_Right"/>
                  <body name="right_foot_link" pos="0 -0.00025 -0.012">
                    <inertial pos="-0.000248 0 -0.00914" quat="0 0.679927 0 0.733279" mass="0.685" diaginertia="0.00268212 0.002385 0.000726885"/>
                    <joint name="Right_Ankle_Roll" axis="1 0 0" range="-0.44 0.44"/>
                    <geom class="visual" material="gray" mesh="right_foot_link"/>
                    <geom name="right_foot" class="foot"/>
                    <site name="right_foot" class="foot"/>
                    <geom class="reward_collision_sphere" pos="0 0 0" size="0.04"/>
                    <geom class="reward_collision_sphere" pos="0.01 0 -0.015" size="0.03"/>
                    <geom class="reward_collision_sphere" pos="0.095 0.023 -0.015" size="0.03"/>
                    <geom class="reward_collision_sphere" pos="-0.07 0.023 -0.015" size="0.03"/>
                  </body>
                </body>
              </body>
            </body>
          </body>
        </body>
      </body>
    </body>
  </worldbody>

  <contact>
    <pair geom1="left_foot" geom2="floor"/>
    <pair geom1="right_foot" geom2="floor"/>
  </contact>

  <actuator>
    <position name="AAHead_yaw" joint="AAHead_yaw" forcerange="-7 7"/>
    <position name="Head_pitch" joint="Head_pitch" forcerange="-7 7"/>
    <position name="Left_Shoulder_Pitch" joint="Left_Shoulder_Pitch" forcerange="-18 18"/>
    <position name="Left_Shoulder_Roll" joint="Left_Shoulder_Roll" forcerange="-18 18"/>
    <position name="Left_Elbow_Pitch" joint="Left_Elbow_Pitch" forcerange="-18 18"/>
    <position name="Left_Elbow_Yaw" joint="Left_Elbow_Yaw" forcerange="-18 18"/>
    <position name="Right_Shoulder_Pitch" joint="Right_Shoulder_Pitch" forcerange="-18 18"/>
    <position name="Right_Shoulder_Roll" joint="Right_Shoulder_Roll" forcerange="-18 18"/>
    <position name="Right_Elbow_Pitch" joint="Right_Elbow_Pitch" forcerange="-18 18"/>
    <position name="Right_Elbow_Yaw" joint="Right_Elbow_Yaw" forcerange="-18 18"/>
    <position name="Waist" joint="Waist" forcerange="-30 30"/>
    <position name="Left_Hip_Pitch" joint="Left_Hip_Pitch" forcerange="-45 45"/>
    <position name="Left_Hip_Roll" joint="Left_Hip_Roll" forcerange="-30 30"/>
    <position name="Left_Hip_Yaw" joint="Left_Hip_Yaw" forcerange="-30 30"/>
    <position name="Left_Knee_Pitch" joint="Left_Knee_Pitch" forcerange="-60 60"/>
    <position name="Left_Ankle_Pitch" joint="Left_Ankle_Pitch" forcerange="-20 20"/>
    <position name="Left_Ankle_Roll" joint="Left_Ankle_Roll" forcerange="-15 15"/>
    <position name="Right_Hip_Pitch" joint="Right_Hip_Pitch" forcerange="-45 45"/>
    <position name="Right_Hip_Roll" joint="Right_Hip_Roll" forcerange="-30 30"/>
    <position name="Right_Hip_Yaw" joint="Right_Hip_Yaw" forcerange="-30 30"/>
    <position name="Right_Knee_Pitch" joint="Right_Knee_Pitch" forcerange="-60 60"/>
    <position name="Right_Ankle_Pitch" joint="Right_Ankle_Pitch" forcerange="-20 20"/>
    <position name="Right_Ankle_Roll" joint="Right_Ankle_Roll" forcerange="-15 15"/>
  </actuator>

  <sensor>
    <gyro site="imu" name="imu_angular_velocity"/>
    <velocimeter site="imu" name="imu_linear_velocity"/>
    <framelinvel objtype="site" objname="left_foot" name="left_foot_global_linear_velocity"/>
    <framelinvel objtype="site" objname="right_foot" name="right_foot_global_linear_velocity"/>
  </sensor>

  <keyframe>
    <key name="home" qpos="0 0 0.6385 1 0 0 0
      0 0
      0 -1.4 0 -0.4
      0 1.4 0 0.4
      0
      -0.4 0 0 0.8 -0.4 0
      -0.4 0 0 0.8 -0.4 0"/>
  </keyframe>
</mujoco>
